/home/apr/data/2020-11-API-misuse/Repair_API_Misuse/api-misuse-repair/2_parse_dl_repos/repo_download_v2/misuse_repos/IntelLabs_nlp-architect/3f63387cff88f0074f1946bbbd1163fbfe97073e/a/solutions/set_expansion/prepare_data.py:26: error: Cannot find implementation or library stub for module named "configargparse"
/home/apr/data/2020-11-API-misuse/Repair_API_Misuse/api-misuse-repair/2_parse_dl_repos/repo_download_v2/misuse_repos/IntelLabs_nlp-architect/3f63387cff88f0074f1946bbbd1163fbfe97073e/a/solutions/set_expansion/prepare_data.py:26: note: See https://mypy.readthedocs.io/en/stable/running_mypy.html#missing-imports
/home/apr/data/2020-11-API-misuse/Repair_API_Misuse/api-misuse-repair/2_parse_dl_repos/repo_download_v2/misuse_repos/IntelLabs_nlp-architect/3f63387cff88f0074f1946bbbd1163fbfe97073e/a/solutions/set_expansion/prepare_data.py:28: error: Cannot find implementation or library stub for module named "nlp_architect.pipelines.spacy_np_annotator"
/home/apr/data/2020-11-API-misuse/Repair_API_Misuse/api-misuse-repair/2_parse_dl_repos/repo_download_v2/misuse_repos/IntelLabs_nlp-architect/3f63387cff88f0074f1946bbbd1163fbfe97073e/a/solutions/set_expansion/prepare_data.py:29: error: Cannot find implementation or library stub for module named "nlp_architect.utils.text"
/home/apr/data/2020-11-API-misuse/Repair_API_Misuse/api-misuse-repair/2_parse_dl_repos/repo_download_v2/misuse_repos/IntelLabs_nlp-architect/3f63387cff88f0074f1946bbbd1163fbfe97073e/a/solutions/set_expansion/prepare_data.py:30: error: Cannot find implementation or library stub for module named "nlp_architect.utils.io"
/home/apr/data/2020-11-API-misuse/Repair_API_Misuse/api-misuse-repair/2_parse_dl_repos/repo_download_v2/misuse_repos/IntelLabs_nlp-architect/3f63387cff88f0074f1946bbbd1163fbfe97073e/a/solutions/set_expansion/prepare_data.py:32: error: Cannot find implementation or library stub for module named "tqdm"
/home/apr/data/2020-11-API-misuse/Repair_API_Misuse/api-misuse-repair/2_parse_dl_repos/repo_download_v2/misuse_repos/IntelLabs_nlp-architect/3f63387cff88f0074f1946bbbd1163fbfe97073e/a/solutions/set_expansion/prepare_data.py:41: error: Need type annotation for "id2group" (hint: "id2group: Dict[<type>, <type>] = ...")
Found 6 errors in 1 file (checked 1 source file)

time cost(in seconds): 1.8730225563049316
